> 异常(Exception)

检查性异常：用户错误或问题引起的异常，程序员无法预见，异常在编译时不能被简单地忽略。

运行时异常：编译时未显现，运行时显现

错误：ERROR，可能与jvm有关，栈溢出等。由java虚拟机生成并抛出，大多数错误与代码编写者所执行的操作无关。

**java建立了异常体系结构，并定义了一个基类java.lang.Throwable作为所有异常的超类。**

![image-20211001150930920](https://raw.githubusercontent.com/wqcblog/picgo-image/master/img/20211001150931.png)

## 抛出，捕获异常

```java
public class App {
    public static void main(String[] args)  {
       try{
            int a=1;
            int b=0;
            System.out.println(a/b);
  }catch(ArithmeticException e){
      System.out.println("程序出现异常，变量b不能为0");//异常被捕获
  } finally {
      System.out.println("执行完毕");//始终执行该操作
  }
    }
}
//try,catch搭配 finally收尾
```

```java
public class App {
    public static void main(String[] args) {
          try{
              new App().a();
          } catch (Error e) {
              System.out.println("Error");
          } catch (Exception e) {
              System.out.println("Exception");
          } catch (Throwable t) {
              System.out.println("Throwable");
          } finally {
              System.out.println("final");
          }
    }

    public void a() {
        b();
    }

    public void b() {
        a();
    }
}
//多个异常从小到大(类比if)
//ctrl+alt+t调出代码块快捷键
```

```java
public class App {
    public static void main(String[] args)  {
       try{
            int a=1;
            int b=0;
            System.out.println(a/b);
  }catch(Exception e){
      e.printStackTrace();//打印错误的栈信息
      System.exit(0);//结束程序
  } finally {
      System.out.println("执行完毕");//始终执行该操作
  }
    }
}
```

```java
public class App {
    public static void main(String[] args)  {
            int a=1;
            int b=0;
         if(b==0)
             throw new ArithmeticException();//主动抛出异常
           System.out.println("a/b");
}
}//主动抛出异常，一般在方法中使用
```

```java
public class Test{
    public static void main(String[] args){
        try{
            new Test().test(1,0);
        }catch(ArithmeticException e){
              e.printStackTrace();
        }
    }
    public void test(int a,int b) throws ArithmeticException{//对方法抛出异常
        if(b==0)
            throw new ArithmeticException();
    }
}
```

## 自定义异常

```java
public class MyException extends Exception {
    private int detail;

    public MyException(int a) {
        this.detail = a;
    }

    public String toString() {
        return "MyException{" + detail + '}';
    }
}
//MyException.java
```

```java
public class Test {
    static void test(int a) throws MyException{
        System.out.println("传递的参数为："+a);
        if (a > 10)
            throw new MyException(a);
            System.out.println("OK");
    }

    public static void main(String[] args) {
         try{
             test(11);
         } catch (MyException e) {
             System.out.println("MyException=>" + e);
         }
     }
}
//Test.java
```

